Workbook

Sheet Raw_Data
A1: Order ID | B1: Order Date | C1: Ship Date | D1: Ship Mode | E1: Customer Name | F1: Segment | G1: Region | H1: City | I1: Category | J1: Sub-Category | K1: Product Name | L1: Quantity | M1: Unit Price | N1: Discount | O1: Sales | P1: Profit
A2: ORD-10216 | B2: 45312 | C2: 45319 | D2: Second Class | E2: IMRAN KHAN | F2: Home Office | G2: East | H2: Sialkot | I2: Technology | J2: Machines | K2: Label Maker | L2: 3 | M2: 641.93 | N2: 0 | O2: 1925.79 | P2: -246.6
A3: ORD-11062 | B3: 45137 | C3: 45140 | D3: Second Class | E3: Fatima Raza | F3: Corporate | G3: South | H3: Hyderabad | I3: Furniture | J3: Furnishings | K3: Desk Lamp | L3: 6 | M3: 367.57 | N3: 0 | O3: 2205.42 | P3: 457.55
A4: ORD-11190 | B4: 45329 | C4: 45335 | D4: Second Class | E4: Zara Iqbal | F4: Consumer | G4: East | H4: Gujranwala | I4: Technology | J4: Copiers | K4: Desktop Copier | L4: 10 | M4: 139.55 | N4: 0 | O4: 1395.5 | P4: 155.48
A5: ORD-10669 | B5: 45355 | C5: 45357 | D5: Second Class | E5: Hina Sheikh | F5: Corporate | G5: East | H5: Sialkot | I5: Furniture | J5: Chairs | K5: Executive Leather Chair | L5: 5 | M5: 427.49 | N5: 0.15 | O5: 2137.45 | P5: -212.93
A6: ORD-10840 | B6: 45186 | C6: 45191 | D6: Standard Class | F6: Home Office | G6: Nort | H6: Islamabad | I6: Furniture | J6: Bookcases | K6: Corner Bookcase | L6: 1 | M6: 896.19 | N6: 0.2 | O6: 896.19 | P6: -21.04
A7: ORD-11011 | B7: 45371 | C7: 45377 | D7: Standard Class | E7: Omar Raza | F7: Home Office | G7: east | H7: Sialkot | I7: Office Supplies | J7: Labels | K7: Address Labels | L7: 10 | M7: 682.06 | N7: 0 | O7: 6820.6 | P7: 1989.09
A8: ORD-10492 | B8: 45236 | C8: 45241 | D8: Standard Class | E8: Zara Qureshi | F8: Home Office | G8: east | H8: Gujranwala | I8: Furniture | J8: Furnishings | K8: Wall Clock | L8: 9 | M8: 410.64 | N8: 0.3 | O8: 3695.76 | P8: 457.47
A9: ORD-10172 | B9: 45275 | C9: 45280 | D9: Same Day | E9: Imran Sheikh | F9: Consumer | G9: Centeral | H9: Faisalabad | I9: Furniture | J9: Bookcases | K9: Wall-Mount Bookcase | L9: 6 | M9: 499.97 | N9: 0.1 | O9: 2999.82 | P9: 197.76
A10: ORD-10063 | B10: 45422 | C10: 45425 | D10: First Class | E10: Usman Qureshi | F10: Home Office | G10: EAST | H10: Gujranwala | I10: Office Supplies | J10: Storage | K10: Storage Box | L10: 7 | M10: 214.04 | N10: 0.3 | O10: 1498.28 | P10: 82.99
A11: ORD-10681 | B11: 45339 | C11: 45340 | D11: Standard Class | E11: Nida Khan | F11: Consumer | G11: central | H11: Multan | I11: Technology | J11: Phones | K11: Office Desk Phone | L11: 2 | M11: 744.77 | N11: 0.3 | O11: 1489.54 | P11: 395.11
A12: ORD-10051 | B12: 45537 | C12: 45544 | D12: Standard Class | E12: Mahnoor Iqbal | F12: Consumer | G12: central | H12: Faisalabad | I12: Office Supplies | J12: Art | K12: Pen Set | L12: 5 | M12: 513.92 | N12: 0 | O12: 2569.6 | P12: 397.81
A13: ORD-10650 | B13: 45488 | C13: 45492 | D13: Second Class | E13: Zara Butt | F13: Corporate | G13: NORTH | H13: Rawalpindi | I13: Furniture | J13: Bookcases | K13: Wall-Mount Bookcase | L13: 4 | M13: 249.91 | N13: 0 | O13: 999.64 | P13: 38.56
A14: ORD-11127 | B14: 45409 | C14: 45416 | D14: Standard Class | E14: Ahmed Malik | F14: Consumer | G14: SOUTH | H14: Hyderabad | I14: Furniture | J14: Furnishings | K14: Floor Mat | L14: 2 | M14: 510.82 | N14: 0 | O14: 1021.64 | P14: -35.09
A15: ORD-10677 | B15: 45012 | C15: 45018 | D15: First Class | E15: Hina Khan | F15: Consumer | G15: CENTRAL | H15: Multan | I15: Office Supplies | J15: Labels | K15: Shipping Labels | L15: 11 | M15: 735.25 | N15: 0.3 | O15: 8087.75 | P15: 224.37
A16: ORD-10170 | B16: 44974 | C16: 44975 | D16: Standard Class | E16: Fatima Qureshi | F16: Corporate | G16: EAST | H16: Sialkot | I16: Furniture | J16: Bookcases | K16: 5-Shelf Bookcase | L16: 3 | M16: 678.27 | N16: 0.2 | O16: 2034.81 | P16: 529.97
A17: ORD-10374 | B17: 44957 | C17: 44964 | D17: First Class | E17: Zara Butt | F17: Home Office | G17: east | H17: Gujranwala | I17: Office Supplies | J17: Art | K17: Highlighter Pack | L17: 4 | M17: 100.56 | N17: 0 | O17: 402.24 | P17: -55.07
A18: ORD-10395 | B18: 45464 | C18: 45467 | D18: First Class | E18: Sana Ansari | F18: Corporate | G18: South | H18: Hyderabad | I18: Furniture | J18: Tables | K18: Round Conference Table | L18: 1 | M18: 720.13 | N18: 0.15 | O18: 720.13 | P18: -52.54
... A23: ORD-10651 | B23: 45034 | C23: 45041 | D23: First Class | E23: Imran Malik | F23: Home Office | G23: north | H23: Rawalpindi | I23: Technology | J23: Accessories | K23: Keyboard | L23: 9 | M23: 317.27 | N23: 0.15 | O23: 2855.43 | P23: 807.23
A24: ORD-10420 | B24: 45372 | C24: 45373 | E24: Ali Malik | F24: Corporate | G24: east | H24: Gujranwala | I24: Technology | J24: Accessories | K24: Keyboard | L24: 9 | M24: 575.49 | N24: 0.3 | O24: 5179.41 | P24: 341.29
A25: ORD-10252 | B25: 45620 | C25: 45625 | D25: First Class | E25: Adeel Qureshi | F25: Corporate | G25: Centeral | H25: Multan | I25: Furniture | J25: Bookcases | K25: Corner Bookcase | L25: 5 | M25: 272.14 | N25: 0 | O25: 1360.7 | P25: 123.65
A26: ORD-10385 | B26: 45116 | C26: 45118 | D26: First Class | E26: Hina Malik | F26: Home Office | G26: NORTH | H26: Lahore | I26: Furniture | J26: Chairs | K26: Folding Chair | L26: 1 | M26: 102.45 | N26: 0 | O26: 102.45 | P26: -7.1
A27: ORD-10204 | B27: 45210 | C27: 45216 | D27: Same Day | E27: Ahmed Chaudhry | F27: Corporate | G27: north | H27: Rawalpindi | I27: Technology | J27: Accessories | K27: Keyboard | L27: 4 | M27: 468.39 | N27: 0.15 | O27: 1873.56 | P27: -104.31
A28: ORD-10325 | B28: 45562 | C28: 45565 | D28: Standard Class | E28: Usman Qureshi | F28: Home Office | G28: WEST | H28: Peshawar | I28: Furniture | J28: Bookcases | K28: Wall-Mount Bookcase | L28: 3 | M28: 53.46 | N28: 0.3 | O28: 160.38 | P28: 9.88
A29: ORD-11015 | B29: 45254 | C29: 45257 | D29: Second Class | E29: Ahmed Iqbal | F29: Consumer | G29: West | H29: Quetta | I29: Technology | J29: Accessories | K29: Wireless Mouse | L29: 9 | M29: 65.83 | N29: 0 | O29: 592.47 | P29: 85.81
A30: ORD-11129 | B30: 45214 | C30: 45220 | D30: Second Class | E30: Adeel Malik | F30: Consumer | G30: Centeral | H30: Multan | I30: Furniture | J30: Bookcases | K30: 5-Shelf Bookcase | L30: -2 | M30: 725.85 | N30: 0.3 | O30: 1451.7 | P30: 216.54
A31: ORD-10714 | B31: 45517 | C31: 45518 | D31: First Class | E31: Ayesha Farooq | F31: Home Office | G31: east | H31: Sialkot | I31: Office Supplies | J31: Storage | K31: Storage Bin | L31: 11 | M31: 899.15 | N31: 0.1 | O31: 9890.65 | P31: 545.9
A32: ORD-10881 | B32: 44960 | C32: 44966 | D32: Standard Class | E32: Tariq Malik | F32: Corporate | G32: West | H32: Peshawar | I32: Furniture | J32: Furnishings | K32: Wall Clock | L32: 12 | M32: 700.05 | N32: 0.2 | O32: 8400.6 | P32: 2894.88
A33: ORD-10611 | B33: 45222 | C33: 45229 | D33: Second Class | E33: Fatima Ansari | F33: Home Office | G33: north | H33: Rawalpindi | I33: Office Supplies | J33: Storage | K33: Storage Box | L33: 1 | M33: 816.44 | N33: 0.2 | O33: 816.44 | P33: 281.01
A34: ORD-10034 | B34: 45443 | C34: 45447 | D34: Second Class | E34: Zara Sheikh | F34: Corporate | G34: Centeral | H34: Multan | I34: Technology | J34: Copiers | K34: Multifunction Copier | L34: 11 | M34: 253.19 | N34: 0.3 | O34: 2785.09 | P34: 308.17
A35: ORD-10757 | B35: 45217 | C35: 45224 | D35: Same Day | E35: Fatima Iqbal | F35: Corporate | G35: central | H35: Multan | I35: Technology | J35: Accessories | K35: USB Cable | L35: 10 | M35: 826.84 | N35: 0 | O35: 8268.4 | P35: -335.46
A36: ORD-10922 | B36: 45321 | C36: 45327 | D36: First Class | E36: Usman Butt | F36: Consumer | G36: north | H36: Lahore | I36: Furniture | J36: Tables | K36: Round Conference Table | L36: 7 | M36: 293.67 | N36: 0.15 | O36: 2055.69 | P36: 185.81
... A45: ORD-10934 | B45: 45209 | C45: 45212 | D45: Same Day | E45: Sara Khan | F45: Consumer | G45: CENTRAL | H45: Faisalabad | I45: Technology | J45: Accessories | K45: Wireless Mouse | L45: 2 | M45: 643.22 | N45: 0.1 | O45: 1286.44 | P45: -36.83
A46: ORD-10264 | B46: 45357 | C46: 45363 | D46: Standard Class | E46: Ayesha Ansari | F46: Corporate | G46: Nort | H46: Islamabad | I46: Technology | J46: Machines | K46: Label Maker | L46: 12 | M46: 557.84 | N46: 0 | O46: 6694.08
A47: ORD-11111 | B47: 45144 | C47: 45149 | D47: First Class | E47: Tariq Malik | F47: Home Office | G47: north | H47: Lahore | I47: Office Supplies | J47: Storage | K47: Storage Bin | L47: 12 | M47: 496.3 | N47: 0.15 | O47: 5955.6 | P47: 1698.24
A48: ORD-10796 | B48: 45310 | C48: 45314 | D48: First Class | E48: Omar Butt | F48: Home Office | G48: EAST | H48: Sialkot | I48: Furniture | J48: Bookcases | K48: 5-Shelf Bookcase | L48: 10 | M48: 27.85 | N48: 0.15 | O48: 278.5 | P48: -12.33
A49: ORD-10565 | B49: 45432 | C49: 45435 | D49: Second Class | E49: Fatima Iqbal | F49: Home Office | G49: NORTH | H49: Islamabad | I49: Technology | J49: Machines | K49: Laser Printer | L49: 2 | M49: 783.58 | N49: 0.15 | O49: 1567.16 | P49: 156.97
A50: ORD-10640 | B50: 45412 | C50: 45414 | D50: Second Class | E50: Faisal Butt | F50: Corporate | G50: North | H50: Rawalpindi | I50: Technology | J50: Accessories | K50: Keyboard | L50: 11 | M50: 651.68 | N50: 0 | O50: 7168.48 | P50: -953.43
A51: ORD-11054 | B51: 45187 | C51: 45192 | D51: Same Day | E51: Ahmed Malik | F51: Home Office | G51: NORTH | H51: Lahore | I51: Office Supplies | J51: Labels | K51: Shipping Labels | L51: 4 | M51: 731.73 | N51: 0 | O51: 2926.92 | P51: 918.77
A52: ORD-10656 | B52: 45219 | C52: 45224 | D52: Same Day | E52: Imran Ansari | F52: Consumer | G52: West | H52: Peshawar | I52: Technology | J52: Machines | K52: Label Maker | L52: 11 | M52: 898.17 | N52: 0.15 | O52: 9879.87 | P52: 1965.51
...

Sheet Cleaning_Formulas
A2: Excel-Level Cleaning Formulas (initial pass, before SQL)
A3: These formulas reference Raw_Data directly and demonstrate TRIM(), PROPER(), and IFERROR() usage. Full/reliable cleaning is done later in SQL — this is the Excel-stage quality pass.
A5: Order ID | B5: Customer Name (Raw) | C5: Customer Name — TRIM+PROPER | D5: Discount (Raw) | E5: Discount — Validated (IFERROR) | F5: Sales — Validated (IFERROR)
A6: ORD-10216 | B6: IMRAN KHAN | C6: =IF(OR(B6="",B6=0), "Unknown Customer", PROPER(TRIM(B6))) -> Imran Khan | D6: 0 | E6: =IFERROR(IF(Raw_Data!N2="", 0, IF(Raw_Data!N2>1, Raw_Data!N2/100, Raw_Data!N2)), 0) -> 0 | F6: =IFERROR(VALUE(Raw_Data!O2), Raw_Data!L2*Raw_Data!M2) -> 1925.79
A7: ORD-11062 | B7: Fatima Raza | C7: =IF(OR(B7="",B7=0), "Unknown Customer", PROPER(TRIM(B7))) -> Fatima Raza | D7: 0 | E7: =IFERROR(IF(Raw_Data!N3="", 0, IF(Raw_Data!N3>1, Raw_Data!N3/100, Raw_Data!N3)), 0) -> 0 | F7: =IFERROR(VALUE(Raw_Data!O3), Raw_Data!L3*Raw_Data!M3) -> 2205.42
A8: ORD-11190 | B8: Zara Iqbal | C8: =IF(OR(B8="",B8=0), "Unknown Customer", PROPER(TRIM(B8))) -> Zara Iqbal | D8: 0 | E8: =IFERROR(IF(Raw_Data!N4="", 0, IF(Raw_Data!N4>1, Raw_Data!N4/100, Raw_Data!N4)), 0) -> 0 | F8: =IFERROR(VALUE(Raw_Data!O4), Raw_Data!L4*Raw_Data!M4) -> 1395.5
A9: ORD-10669 | B9: Hina Sheikh | C9: =IF(OR(B9="",B9=0), "Unknown Customer", PROPER(TRIM(B9))) -> Hina Sheikh | D9: 0.15 | E9: =IFERROR(IF(Raw_Data!N5="", 0, IF(Raw_Data!N5>1, Raw_Data!N5/100, Raw_Data!N5)), 0) -> 0.15 | F9: =IFERROR(VALUE(Raw_Data!O5), Raw_Data!L5*Raw_Data!M5) -> 2137.45
A10: ORD-10840 | B10: 0 | C10: =IF(OR(B10="",B10=0), "Unknown Customer", PROPER(TRIM(B10))) -> Unknown Customer | D10: 0.2 | E10: =IFERROR(IF(Raw_Data!N6="", 0, IF(Raw_Data!N6>1, Raw_Data!N6/100, Raw_Data!N6)), 0) -> 0.2 | F10: =IFERROR(VALUE(Raw_Data!O6), Raw_Data!L6*Raw_Data!M6) -> 896.19
A11: ORD-11011 | B11: Omar Raza | C11: =IF(OR(B11="",B11=0), "Unknown Customer", PROPER(TRIM(B11))) -> Omar Raza | D11: 0 | E11: =IFERROR(IF(Raw_Data!N7="", 0, IF(Raw_Data!N7>1, Raw_Data!N7/100, Raw_Data!N7)), 0) -> 0 | F11: =IFERROR(VALUE(Raw_Data!O7), Raw_Data!L7*Raw_Data!M7) -> 6820.6
A12: ORD-10492 | B12: Zara Qureshi | C12: =IF(OR(B12="",B12=0), "Unknown Customer", PROPER(TRIM(B12))) -> Zara Qureshi | D12: 0.3 | E12: =IFERROR(IF(Raw_Data!N8="", 0, IF(Raw_Data!N8>1, Raw_Data!N8/100, Raw_Data!N8)), 0) -> 0.3 | F12: =IFERROR(VALUE(Raw_Data!O8), Raw_Data!L8*Raw_Data!M8) -> 3695.76
A13: ORD-10172 | B13: Imran Sheikh | C13: =IF(OR(B13="",B13=0), "Unknown Customer", PROPER(TRIM(B13))) -> Imran Sheikh | D13: 0.1 | E13: =IFERROR(IF(Raw_Data!N9="", 0, IF(Raw_Data!N9>1, Raw_Data!N9/100, Raw_Data!N9)), 0) -> 0.1 | F13: =IFERROR(VALUE(Raw_Data!O9), Raw_Data!L9*Raw_Data!M9) -> 2999.82
A14: ORD-10063 | B14: Usman Qureshi | C14: =IF(OR(B14="",B14=0), "Unknown Customer", PROPER(TRIM(B14))) -> Usman Qureshi | D14: 0.3 | E14: =IFERROR(IF(Raw_Data!N10="", 0, IF(Raw_Data!N10>1, Raw_Data!N10/100, Raw_Data!N10)), 0) -> 0.3 | F14: =IFERROR(VALUE(Raw_Data!O10), Raw_Data!L10*Raw_Data!M10) -> 1498.28
A15: ORD-10681 | B15: Nida Khan | C15: =IF(OR(B15="",B15=0), "Unknown Customer", PROPER(TRIM(B15))) -> Nida Khan | D15: 0.3 | E15: =IFERROR(IF(Raw_Data!N11="", 0, IF(Raw_Data!N11>1, Raw_Data!N11/100, Raw_Data!N11)), 0) -> 0.3 | F15: =IFERROR(VALUE(Raw_Data!O11), Raw_Data!L11*Raw_Data!M11) -> 1489.54
A16: ORD-10051 | B16: Mahnoor Iqbal | C16: =IF(OR(B16="",B16=0), "Unknown Customer", PROPER(TRIM(B16))) -> Mahnoor Iqbal | D16: 0 | E16: =IFERROR(IF(Raw_Data!N12="", 0, IF(Raw_Data!N12>1, Raw_Data!N12/100, Raw_Data!N12)), 0) -> 0 | F16: =IFERROR(VALUE(Raw_Data!O12), Raw_Data!L12*Raw_Data!M12) -> 2569.6
A17: ORD-10650 | B17: Zara Butt | C17: =IF(OR(B17="",B17=0), "Unknown Customer", PROPER(TRIM(B17))) -> Zara Butt | D17: 0 | E17: =IFERROR(IF(Raw_Data!N13="", 0, IF(Raw_Data!N13>1, Raw_Data!N13/100, Raw_Data!N13)), 0) -> 0 | F17: =IFERROR(VALUE(Raw_Data!O13), Raw_Data!L13*Raw_Data!M13) -> 999.64
A18: ORD-11127 | B18: Ahmed Malik | C18: =IF(OR(B18="",B18=0), "Unknown Customer", PROPER(TRIM(B18))) -> Ahmed Malik | D18: 0 | E18: =IFERROR(IF(Raw_Data!N14="", 0, IF(Raw_Data!N14>1, Raw_Data!N14/100, Raw_Data!N14)), 0) -> 0 | F18: =IFERROR(VALUE(Raw_Data!O14), Raw_Data!L14*Raw_Data!M14) -> 1021.64
A19: ORD-10677 | B19: Hina Khan | C19: =IF(OR(B19="",B19=0), "Unknown Customer", PROPER(TRIM(B19))) -> Hina Khan | D19: 0.3 | E19: =IFERROR(IF(Raw_Data!N15="", 0, IF(Raw_Data!N15>1, Raw_Data!N15/100, Raw_Data!N15)), 0) -> 0.3 | F19: =IFERROR(VALUE(Raw_Data!O15), Raw_Data!L15*Raw_Data!M15) -> 8087.75
A20: ORD-10170 | B20: Fatima Qureshi | C20: =IF(OR(B20="",B20=0), "Unknown Customer", PROPER(TRIM(B20))) -> Fatima Qureshi | D20: 0.2 | E20: =IFERROR(IF(Raw_Data!N16="", 0, IF(Raw_Data!N16>1, Raw_Data!N16/100, Raw_Data!N16)), 0) -> 0.2 | F20: =IFERROR(VALUE(Raw_Data!O16), Raw_Data!L16*Raw_Data!M16) -> 2034.81
A21: ORD-10374 | B21: Zara Butt | C21: =IF(OR(B21="",B21=0), "Unknown Customer", PROPER(TRIM(B21))) -> Zara Butt | D21: 0 | E21: =IFERROR(IF(Raw_Data!N17="", 0, IF(Raw_Data!N17>1, Raw_Data!N17/100, Raw_Data!N17)), 0) -> 0 | F21: =IFERROR(VALUE(Raw_Data!O17), Raw_Data!L17*Raw_Data!M17) -> 402.24
A22: ORD-10395 | B22: Sana Ansari | C22: =IF(OR(B22="",B22=0), "Unknown Customer", PROPER(TRIM(B22))) -> Sana Ansari | D22: 0.15 | E22: =IFERROR(IF(Raw_Data!N18="", 0, IF(Raw_Data!N18>1, Raw_Data!N18/100, Raw_Data!N18)), 0) -> 0.15 | F22: =IFERROR(VALUE(Raw_Data!O18), Raw_Data!L18*Raw_Data!M18) -> 720.13
... A140: ORD-10407 | B140: Fatima Raza | C140: =IF(OR(B140="",B140=0), "Unknown Customer", PROPER(TRIM(B140))) -> Fatima Raza | D140: 0.2 | E140: =IFERROR(IF(Raw_Data!N136="", 0, IF(Raw_Data!N136>1, Raw_Data!N136/100, Raw_Data!N136)), 0) -> 0.2 | F140: =IFERROR(VALUE(Raw_Data!O136), Raw_Data!L136*Raw_Data!M136) -> 2577
B141: 0 | C141: =IF(OR(B141="",B141=0), "Unknown Customer", PROPER(TRIM(B141))) -> Unknown Customer | D141: 0 | E141: =IFERROR(IF(Raw_Data!N137="", 0, IF(Raw_Data!N137>1, Raw_Data!N137/100, Raw_Data!N137)), 0) -> 0 | F141: =IFERROR(VALUE(Raw_Data!O137), Raw_Data!L137*Raw_Data!M137) -> 0
B142: Rabia Chaudhry | C142: =IF(OR(B142="",B142=0), "Unknown Customer", PROPER(TRIM(B142))) -> Rabia Chaudhry | D142: 0 | E142: =IFERROR(IF(Raw_Data!N138="", 0, IF(Raw_Data!N138>1, Raw_Data!N138/100, Raw_Data!N138)), 0) -> 0 | F142: =IFERROR(VALUE(Raw_Data!O138), Raw_Data!L138*Raw_Data!M138) -> 521.92
B143: Faisal Sheikh | C143: =IF(OR(B143="",B143=0), "Unknown Customer", PROPER(TRIM(B143))) -> Faisal Sheikh | D143: 0.15 | E143: =IFERROR(IF(Raw_Data!N139="", 0, IF(Raw_Data!N139>1, Raw_Data!N139/100, Raw_Data!N139)), 0) -> 0.15 | F143: =IFERROR(VALUE(Raw_Data!O139), Raw_Data!L139*Raw_Data!M139) -> 245.9
B144: Ahmed Qureshi | C144: =IF(OR(B144="",B144=0), "Unknown Customer", PROPER(TRIM(B144))) -> Ahmed Qureshi | D144: 0 | E144: =IFERROR(IF(Raw_Data!N140="", 0, IF(Raw_Data!N140>1, Raw_Data!N140/100, Raw_Data!N140)), 0) -> 0 | F144: =IFERROR(VALUE(Raw_Data!O140), Raw_Data!L140*Raw_Data!M140) -> 345.56
B145: Ali Qureshi | C145: =IF(OR(B145="",B145=0), "Unknown Customer", PROPER(TRIM(B145))) -> Ali Qureshi | D145: 0.3 | E145: =IFERROR(IF(Raw_Data!N141="", 0, IF(Raw_Data!N141>1, Raw_Data!N141/100, Raw_Data!N141)), 0) -> 0.3 | F145: =IFERROR(VALUE(Raw_Data!O141), Raw_Data!L141*Raw_Data!M141) -> 1066.72
B146: Ayesha Qureshi | C146: =IF(OR(B146="",B146=0), "Unknown Customer", PROPER(TRIM(B146))) -> Ayesha Qureshi | D146: 0 | E146: =IFERROR(IF(Raw_Data!N142="", 0, IF(Raw_Data!N142>1, Raw_Data!N142/100, Raw_Data!N142)), 0) -> 0 | F146: =IFERROR(VALUE(Raw_Data!O142), Raw_Data!L142*Raw_Data!M142) -> 2123.6
B147: Ayesha Butt | C147: =IF(OR(B147="",B147=0), "Unknown Customer", PROPER(TRIM(B147))) -> Ayesha Butt | D147: 0 | E147: =IFERROR(IF(Raw_Data!N143="", 0, IF(Raw_Data!N143>1, Raw_Data!N143/100, Raw_Data!N143)), 0) -> 0 | F147: =IFERROR(VALUE(Raw_Data!O143), Raw_Data!L143*Raw_Data!M143) -> 1296.96
B148: Tariq Butt | C148: =IF(OR(B148="",B148=0), "Unknown Customer", PROPER(TRIM(B148))) -> Tariq Butt | D148: 0.15 | E148: =IFERROR(IF(Raw_Data!N144="", 0, IF(Raw_Data!N144>1, Raw_Data!N144/100, Raw_Data!N144)), 0) -> 0.15 | F148: =IFERROR(VALUE(Raw_Data!O144), Raw_Data!L144*Raw_Data!M144) -> 2355.84
B149: Tariq Malik | C149: =IF(OR(B149="",B149=0), "Unknown Customer", PROPER(TRIM(B149))) -> Tariq Malik | D149: 0.15 | E149: =IFERROR(IF(Raw_Data!N145="", 0, IF(Raw_Data!N145>1, Raw_Data!N145/100, Raw_Data!N145)), 0) -> 0.15 | F149: =IFERROR(VALUE(Raw_Data!O145), Raw_Data!L145*Raw_Data!M145) -> 5208.12
B150: Omar Qureshi | C150: =IF(OR(B150="",B150=0), "Unknown Customer", PROPER(TRIM(B150))) -> Omar Qureshi | D150: 0 | E150: =IFERROR(IF(Raw_Data!N146="", 0, IF(Raw_Data!N146>1, Raw_Data!N146/100, Raw_Data!N146)), 0) -> 0 | F150: =IFERROR(VALUE(Raw_Data!O146), Raw_Data!L146*Raw_Data!M146) -> 8912.4
B151: Ali Iqbal | C151: =IF(OR(B151="",B151=0), "Unknown Customer", PROPER(TRIM(B151))) -> Ali Iqbal | D151: 0.1 | E151: =IFERROR(IF(Raw_Data!N147="", 0, IF(Raw_Data!N147>1, Raw_Data!N147/100, Raw_Data!N147)), 0) -> 0.1 | F151: =IFERROR(VALUE(Raw_Data!O147), Raw_Data!L147*Raw_Data!M147) -> 4969.5
B152: Bilal Iqbal | C152: =IF(OR(B152="",B152=0), "Unknown Customer", PROPER(TRIM(B152))) -> Bilal Iqbal | D152: 0 | E152: =IFERROR(IF(Raw_Data!N148="", 0, IF(Raw_Data!N148>1, Raw_Data!N148/100, Raw_Data!N148)), 0) -> 0 | F152: =IFERROR(VALUE(Raw_Data!O148), Raw_Data!L148*Raw_Data!M148) -> 827.31
B153: Hina Butt | C153: =IF(OR(B153="",B153=0), "Unknown Customer", PROPER(TRIM(B153))) -> Hina Butt | D153: 0.1 | E153: =IFERROR(IF(Raw_Data!N149="", 0, IF(Raw_Data!N149>1, Raw_Data!N149/100, Raw_Data!N149)), 0) -> 0.1 | F153: =IFERROR(VALUE(Raw_Data!O149), Raw_Data!L149*Raw_Data!M149) -> 8087.4
... B172: Imran Butt | C172: =IF(OR(B172="",B172=0), "Unknown Customer", PROPER(TRIM(B172))) -> Imran Butt | D172: 0.1 | E172: =IFERROR(IF(Raw_Data!N168="", 0, IF(Raw_Data!N168>1, Raw_Data!N168/100, Raw_Data!N168)), 0) -> 0.1 | F172: =IFERROR(VALUE(Raw_Data!O168), Raw_Data!L168*Raw_Data!M168) -> 191.04
B173: 0 | C173: =IF(OR(B173="",B173=0), "Unknown Customer", PROPER(TRIM(B173))) -> Unknown Customer | D173: 0 | E173: =IFERROR(IF(Raw_Data!N169="", 0, IF(Raw_Data!N169>1, Raw_Data!N169/100, Raw_Data!N169)), 0) -> 0 | F173: =IFERROR(VALUE(Raw_Data!O169), Raw_Data!L169*Raw_Data!M169) -> 5378.72
B174: Usman Farooq | C174: =IF(OR(B174="",B174=0), "Unknown Customer", PROPER(TRIM(B174))) -> Usman Farooq | D174: 0.3 | E174: =IFERROR(IF(Raw_Data!N170="", 0, IF(Raw_Data!N170>1, Raw_Data!N170/100, Raw_Data!N170)), 0) -> 0.3 | F174: =IFERROR(VALUE(Raw_Data!O170), Raw_Data!L170*Raw_Data!M170) -> 2255.22
B175: Rabia Khan | C175: =IF(OR(B175="",B175=0), "Unknown Customer", PROPER(TRIM(B175))) -> Rabia Khan | D175: 0 | E175: =IFERROR(IF(Raw_Data!N171="", 0, IF(Raw_Data!N171>1, Raw_Data!N171/100, Raw_Data!N171)), 0) -> 0 | F175: =IFERROR(VALUE(Raw_Data!O171), Raw_Data!L171*Raw_Data!M171) -> 8099.41
B176: Usman Farooq | C176: =IF(OR(B176="",B176=0), "Unknown Customer", PROPER(TRIM(B176))) -> Usman Farooq | D176: 0.2 | E176: =IFERROR(IF(Raw_Data!N172="", 0, IF(Raw_Data!N172>1, Raw_Data!N172/100, Raw_Data!N172)), 0) -> 0.2 | F176: =IFERROR(VALUE(Raw_Data!O172), Raw_Data!L172*Raw_Data!M172) -> 5382.48
B177: Sana Chaudhry | C177: =IF(OR(B177="",B177=0), "Unknown Customer", PROPER(TRIM(B177))) -> Sana Chaudhry | D177: 0.2 | E177: =IFERROR(IF(Raw_Data!N173="", 0, IF(Raw_Data!N173>1, Raw_Data!N173/100, Raw_Data!N173)), 0) -> 0.2 | F177: =IFERROR(VALUE(Raw_Data!O173), Raw_Data!L173*Raw_Data!M173) -> 475.09
...

Sheet Category_Summary
A1: Category-Wise Sales Summary (Pivot-style sanity check)
A2: Built with SUMIFS/COUNTIFS against Raw_Data — a quick sanity check before the data moves into SQL.
A4: Category | B4: Order Count | C4: Total Sales | D4: Total Profit
A5: Furniture | B5: =COUNTIF(Raw_Data!I:I,A5) -> 423 | C5: =SUMIF(Raw_Data!I:I,A5,Raw_Data!O:O) -> 1292635.8 | D5: =SUMIF(Raw_Data!I:I,A5,Raw_Data!P:P) -> 136611.15
A6: Office Supplies | B6: =COUNTIF(Raw_Data!I:I,Category_Summary!A6) -> 430 | C6: =SUMIF(Raw_Data!I:I,A6,Raw_Data!O:O) -> 1301622.1 | D6: =SUMIF(Raw_Data!I:I,A6,Raw_Data!P:P) -> 121206.68
A7: Technology | B7: =COUNTIF(Raw_Data!I:I,A7) -> 392 | C7: =SUMIF(Raw_Data!I:I,A7,Raw_Data!O:O) -> 1109618.4 | D7: =SUMIF(Raw_Data!I:I,A7,Raw_Data!P:P) -> 102322.87
A8: TOTAL | B8: =SUM(B5:B7) -> 1245 | C8: =SUM(C5:C7) -> 3703876.3 | D8: =SUM(D5:D7) -> 360140.7

Sheet Data_Quality_Notes
A1: Phase 1 — Data Quality Notes (Excel Review)
A4: Issue Found | B4: Action Taken
A5: Duplicate Order IDs (~45 rows) | B5: Flagged with conditional formatting here; removed properly in SQL using ROWID/MIN dedup logic (Phase 2).
A6: Blank Customer Name / Region / City / Ship Mode / Discount / Profit | B6: Flagged with conditional formatting; SQL view fills sensible defaults (e.g. 'Unknown Customer', 0 discount).
A7: Inconsistent text casing in Customer Name ('ALI KHAN', 'ali khan', ' Ali Khan ') | B7: TRIM()+PROPER() applied on Cleaning_Formulas sheet; standardized further in SQL.
A8: Region typos and case issues ('nort', 'NORTH', ' South ') | B8: Standardized to 5 canonical regions in SQL cleaning view using CASE/LOWER/TRIM.
A9: Negative Quantity values (data entry errors) | B9: Corrected using ABS() in SQL.
A10: Discount stored as whole numbers instead of decimals (e.g. 20 instead of 0.20) | B10: Detected and divided by 100 where Discount > 1, in both Excel formulas and SQL.
A11: Non-numeric 'N/A' values in Sales column | B11: IFERROR()+VALUE() fallback in Excel; SQL recomputes Sales = Quantity x Unit Price when invalid.
A12: Mixed date formats (YYYY-MM-DD and DD/MM/YYYY) | B12: Normalized to ISO format (YYYY-MM-DD) in the SQL cleaning view.
A13: One fully blank row | B13: Excluded in SQL WHERE clause (Order ID IS NOT NULL).
